Workbook

Sheet Unternehmen
A1: Firma_ID | B1: Unternehmen | C1: Finanzwert (0/1) | D1: Branche (vorlaeufig) | E1: KPI1_Definition (Umsatzgroesse) | F1: KPI2_Definition (op. Ergebnisgroesse) | G1: Anmerkung
A2: ADS | B2: adidas AG | C2: 0 | D2: Konsumgueter | E2: Umsatzwachstum | F2: Operative Marge / Betriebsergebnis
A3: ALV | B3: Allianz SE | C3: 1 | D3: Versicherungen | E3: Umsatz | F3: Operatives Ergebnis | G3: Konzernumsatz-Prognose nur qualitativ -> KPI1 fehlend
A4: BAS | B4: BASF SE | C4: 0 | D4: Chemie | E4: Umsatzwachstum | F4: EBIT/EBITDA*
A5: BAYN | B5: Bayer AG | C5: 0 | D5: Pharma & Healthcare | E5: Umsatzerlöse | F5: EBITDA
A6: BEI | B6: Beiersdorf AG | C6: 0 | D6: Konsumgueter | E6: Umsatzentwicklung | F6: EBIT-Umsatzrendite | G6: Alle Geschäftsberichte zum Download unter https://www.beiersdorf.de/investor-relations/finanzberichte/finanzberichte-und-praesentationen
A7: BMW | B7: BMW AG | C7: 0 | D7: Automobile | E7: nicht prognostiziert | F7: EBIT-Marge | G7: Nur Segment Automobile betrachtet, Segment Motorräder außen vor gelassen (im vergleich ist das Segment winzig). Umsatzprognose wird nicht durchgeführt, da BMW intern nicht über Umsatz steuert und DRS 20 verlangt Prognosen nur für die intern verwendeten bedeutsamsten Leistungsindikatoren.
A8: CON | B8: Continental AG | C8: 0 | D8: Automobile | E8: Umsatz | F8: EBIT-Marge
A9: 1COV | B9: Covestro AG | C9: 0 | D9: Chemie | E9: nicht prognostiziert | F9: EBITDA | G9: Umsatz als KPI fehlt
A10: DAI | B10: Daimler AG | C10: 0 | D10: Automobile | E10: Umsatz | F10: Bereinigte Umsatzrendite MB Cars & Vans | G10: 12/2021 Spin-off Daimler Truck; ab GB 2021 Mercedes-Benz-Group; ab 2022 ggf. Segment Cars separat.
A11: DBK | B11: Deutsche Bank AG | C11: 1 | D11: Banken | E11: Erträge Konzern | F11: Eigenkapitalrendite nach Steuern | G11: KPI2: Jahresprognose nur im GB 2019 für 2020 und GB 2021 für 2022, übrige Jahre nur Mittelfristziele -> fehlend
A12: DB1 | B12: Deutsche Boerse AG | C12: 1 | D12: Finanzdienstleister | E12: Nettoerlöse | F12: EBITDA
A13: DPW | B13: Deutsche Post AG | C13: 0 | D13: Transport & Logistik | E13: nicht prognostiziert | F13: Konzern-EBIT | G13: KPI1 nicht prognostiziert, alle Jahre fehlend
A14: DTE | B14: Deutsche Telekom AG | C14: 0 | D14: Telekommunikation | E14: Umsatz | F14: Bereinigte EBITDA AL
A15: EOAN | B15: E.ON SE | C15: 0 | D15: Versorger | E15: nicht prognostiziert | F15: EBIT/EBITDA | G15: KPI1 nicht prognostiziert, alle Jahre fehlend KPI2: Für 2020 und 2021 EBIT; für 2022, 2023 und 2024 EBITDA
A16: FRE | B16: Fresenius SE & Co. KGaA | C16: 0 | D16: Pharma & Healthcare | E16: Umsatz | F16: Konzernergebnis/EBIT | G16: KPI2: Konzernergebnis für 2020 bis 2022, ab 2023 EBIT
A17: FME | B17: Fresenius Medical Care AG & Co. KGaA | C17: 0 | D17: Pharma & Healthcare | E17: Umsatzerlöse | F17: Operatives Ergebnis
A18: HEI | B18: HeidelbergCement AG | C18: 0 | D18: Bau | E18: Umsatz | F18: Ergebnis des laufenden Geschäftsbetriebs (RCO)
A19: HEN3 | B19: Henkel AG & Co. KGaA | C19: 0 | D19: Konsumgueter | E19: Organisches Umsatzwachstum | F19: EBIT-Marge (bereinigt)
A20: IFX | B20: Infineon Technologies AG | C20: 0 | D20: Technologie | E20: Umsatzwachstum | F20: Segmentergebnis-Marge
B21: Linde plc | D21: Chemie | E21: Ausgeschlossen, Begründung unter Kapitel 3.1
A22: LHA | B22: Deutsche Lufthansa AG | C22: 0 | D22: Transport & Logistik | F22: Bereinigtes EBIT
A23: MRK | B23: Merck KGaA | C23: 0 | D23: Pharma & Healthcare | E23: Umsatzerlöse | F23: EBITDA pre
A24: MTX | B24: MTU Aero Engines AG | C24: 0 | D24: Industrie | E24: Umsatz(/Bereinigter Umsatz) | F24: Bereinigtes EBIT/ EBIT-Marge
A25: MUV2 | B25: Muenchener Rueck AG | C25: 1 | D25: Versicherungen | E25: nicht prognostiziert | F25: Konzernergebnis | G25: Umsatz -> KPI1 fehlend
A26: RWE | B26: RWE AG | C26: 0 | D26: Versorger | E26: nicht prognostiziert | F26: Bereinigtes EBITDA | G26: Umsatz -> KPI1 fehlend
A27: SAP | B27: SAP SE | C27: 0 | D27: Technologie | E27: Cloud- und Softwareerlöse | F27: Betriebsergebnis Non-IFRS (wb.) | G27: Prognose Non-IFRS + waehrungsbereinigt
A28: SIE | B28: Siemens AG | C28: 0 | D28: Industrie | E28: Umsatzerlöse | F28: EBITA-Marge / EPS pre PPA | G28: Geschaeftsjahr endet 30.09. KPI2: Ergebnismarge Industrial Business (2020-2021), ab GJ 2022 EPS pre PPA wegen geänderter Konzernsteuerung nach Siemens-Energy-Spin-off 09/2020
A29: VOW3 | B29: Volkswagen AG | C29: 0 | D29: Automobile | E29: Umsatzerlöse | F29: Operative Umsatzrendite
A30: VNA | B30: Vonovia SE | C30: 0 | D30: Immobilien | E30: Group FFO | F30: Bereinigtes EBITDA | G30: KPI1: Group Funds from Operations -> wichtigste operative Kennzahl für Rentabilität und Cashflow in der Immobilienbranche. KPI1 ab 2023 fehlend (Prognose für 2024 fehlt).
B31: Wirecard | D31: Technologie | E31: Ausgeschlossen, Begründung unter Kapitel 3.1
A33: Stichprobe: DAX30 zum Stichtag 01.01.2020 (Stand nach Indexanpassung 09/2019). Ausgeschlossen: Wirecard AG (Insolvenz 2020, keine verlaesslichen Ist-Werte) und Linde plc (irische Gesellschaft, US-GAAP, keine DRS-20-Prognoseberichtspflicht) -> 28 Unternehmen. Quelle: STOXX, Historical Index Compositions of the Equity- and Strategy Indices.

Sheet Daten
A1: Firma_ID | B1: Ist_Jahr | C1: KPI | D1: GB_Prognosequelle | E1: Seite_Prognose | F1: Prognoseform | G1: Angabetyp | H1: Einheit | I1: Prog_Untergrenze | J1: Prog_Obergrenze | K1: Basiswert_Vorjahr | L1: Ist_Wert | M1: Veränderung zum Vorjahr | N1: Rahmensprengung | O1: GB_Ist_Quelle | P1: Seite_Ist | Q1: Anmerkung | R1: Prognose_final | S1: Fehler (Prog.-Ist) | T1: Rel_Fehler (nur absolut) | U1: APE (nur absolut) | V1: Treffer_Bandbreite (1/0) | W1: Prognose_Wortlaut | X1: Trefferkategorie | Y1: Fehler_PP (nur %-KPI) | Z1: Branche
A2: ADS | B2: 2020 | C2: Umsatz | D2: 2019: https://report.adidas-group.com/2019/de/serviceseiten/downloads/files/adidas_geschaeftsbericht_2019.pdf | E2: 129 | F2: Bandbreite | G2: Wachstumsrate % | H2: % (wb. Wachstumsrate) | I2: 0.06 | J2: 0.08 | K2: 0.06 | L2: -0.14 | M2: -20 PP | N2: -20 PP | O2: 2020: https://report.adidas-group.com/2020/de/serviceseiten/downloads/files/annual-report-adidas-gb20.pdf | P2: 200 | R2: =IF(NOT(ISNUMBER(I2)),"",IF(F2="Mindestprognose",I2,IF(ISNUMBER(J2),(I2+J2)/2,I2))) -> 0.07 | S2: =IF(OR(R2="",NOT(ISNUMBER(L2))),"",R2-L2) -> 0.21 | T2: =IF(OR(S2="",G2<>"absolut",NOT(ISNUMBER(L2)),L2=0),"",S2/ABS(L2)) | U2: =IF(T2="","",ABS(T2)) | V2: =IF(OR(F2="Punkt",NOT(ISNUMBER(L2))),"",IF(F2="Mindestprognose",IF(L2>=I2,1,0),IF(AND(ISNUMBER(I2),ISNUMBER(J2),I2<>J2),IF(AND(L2>=I2,L2<=J2),1,0),""))) -> 0 | X2: =IF(OR(F2="qualitativ",F2="fehlend",NOT(ISNUMBER(L2))),"nicht auswertbar",IF(F2="Punkt","Punktprognose",IF(AND(ISNUMBER(I2),ISNUMBER(J2),I2<>J2),IF(L2<I2,"unterhalb",IF(L2>J2,"oberhalb","innerhalb")),"nicht auswertbar"))) -> unterhalb | Y2: =IF(AND(ISNUMBER(S2),OR(G2="Marge %",G2="Wachstumsrate %")),ABS(S2),"") -> 0.21 | Z2: =IFERROR(VLOOKUP(A2,Unternehmen!$A:$D,4,FALSE()),"") -> Konsumgueter
A3: ADS | B3: 2020 | C3: Operative Ergebnisgroesse | D3: 2019: https://report.adidas-group.com/2019/de/serviceseiten/downloads/files/adidas_geschaeftsbericht_2019.pdf | E3: 130 | F3: Bandbreite | G3: Marge % | H3: % (op. Marge) | I3: 0.115 | J3: 0.118 | K3: 0.113 | L3: 0.038 | M3: -7,5 PP | N3: -0,20 PP | O3: 2020: https://report.adidas-group.com/2020/de/serviceseiten/downloads/files/annual-report-adidas-gb20.pdf | P3: 200 | R3: =IF(NOT(ISNUMBER(I3)),"",IF(F3="Mindestprognose",I3,IF(ISNUMBER(J3),(I3+J3)/2,I3))) -> 0.1165 | S3: =IF(OR(R3="",NOT(ISNUMBER(L3))),"",R3-L3) -> 0.0785 | T3: =IF(OR(S3="",G3<>"absolut",NOT(ISNUMBER(L3)),L3=0),"",S3/ABS(L3)) | U3: =IF(T3="","",ABS(T3)) | V3: =IF(OR(F3="Punkt",NOT(ISNUMBER(L3))),"",IF(F3="Mindestprognose",IF(L3>=I3,1,0),IF(AND(ISNUMBER(I3),ISNUMBER(J3),I3<>J3),IF(AND(L3>=I3,L3<=J3),1,0),""))) -> 0 | X3: =IF(OR(F3="qualitativ",F3="fehlend",NOT(ISNUMBER(L3))),"nicht auswertbar",IF(F3="Punkt","Punktprognose",IF(AND(ISNUMBER(I3),ISNUMBER(J3),I3<>J3),IF(L3<I3,"unterhalb",IF(L3>J3,"oberhalb","innerhalb")),"nicht auswertbar"))) -> unterhalb | Y3: =IF(AND(ISNUMBER(S3),OR(G3="Marge %",G3="Wachstumsrate %")),ABS(S3),"") -> 0.0785 | Z3: =IFERROR(VLOOKUP(A3,Unternehmen!$A:$D,4,FALSE()),"") -> Konsumgueter
A4: ADS | B4: 2021 | C4: Umsatz | D4: 2020: https://report.adidas-group.com/2020/de/serviceseiten/downloads/files/annual-report-adidas-gb20.pdf | E4: 178 | F4: Bandbreite | G4: Wachstumsrate % | H4: % (wb. Wachstumsrate) | I4: 0.15 | J4: 0.19 | K4: -0.14 | L4: 0.16 | M4: 30 PP | N4: im Rahmen | O4: 2021: https://report.adidas-group.com/2021/de/serviceseiten/downloads/files/annual-report-adidas-gb21.pdf | P4: 3 | R4: =IF(NOT(ISNUMBER(I4)),"",IF(F4="Mindestprognose",I4,IF(ISNUMBER(J4),(I4+J4)/2,I4))) -> 0.17 | S4: =IF(OR(R4="",NOT(ISNUMBER(L4))),"",R4-L4) -> 0.01 | T4: =IF(OR(S4="",G4<>"absolut",NOT(ISNUMBER(L4)),L4=0),"",S4/ABS(L4)) | U4: =IF(T4="","",ABS(T4)) | V4: =IF(OR(F4="Punkt",NOT(ISNUMBER(L4))),"",IF(F4="Mindestprognose",IF(L4>=I4,1,0),IF(AND(ISNUMBER(I4),ISNUMBER(J4),I4<>J4),IF(AND(L4>=I4,L4<=J4),1,0),""))) -> 1 | X4: =IF(OR(F4="qualitativ",F4="fehlend",NOT(ISNUMBER(L4))),"nicht auswertbar",IF(F4="Punkt","Punktprognose",IF(AND(ISNUMBER(I4),ISNUMBER(J4),I4<>J4),IF(L4<I4,"unterhalb",IF(L4>J4,"oberhalb","innerhalb")),"nicht auswertbar"))) -> innerhalb | Y4: =IF(AND(ISNUMBER(S4),OR(G4="Marge %",G4="Wachstumsrate %")),ABS(S4),"") -> 0.01 | Z4: =IFERROR(VLOOKUP(A4,Unternehmen!$A:$D,4,FALSE()),"") -> Konsumgueter
A5: ADS | B5: 2021 | C5: Operative Ergebnisgroesse | D5: 2020: https://report.adidas-group.com/2020/de/serviceseiten/downloads/files/annual-report-adidas-gb20.pdf | E5: 179 | F5: Bandbreite | G5: Marge % | H5: % (op. Marge) | I5: 0.09 | J5: 0.1 | K5: 0.04 | L5: 0.094 | M5: 5,3 PP | N5: im Rahmen | O5: 2021: https://report.adidas-group.com/2021/de/serviceseiten/downloads/files/annual-report-adidas-gb21.pdf | P5: 3 | R5: =IF(NOT(ISNUMBER(I5)),"",IF(F5="Mindestprognose",I5,IF(ISNUMBER(J5),(I5+J5)/2,I5))) -> 0.095 | S5: =IF(OR(R5="",NOT(ISNUMBER(L5))),"",R5-L5) -> 0.001 | T5: =IF(OR(S5="",G5<>"absolut",NOT(ISNUMBER(L5)),L5=0),"",S5/ABS(L5)) | U5: =IF(T5="","",ABS(T5)) | V5: =IF(OR(F5="Punkt",NOT(ISNUMBER(L5))),"",IF(F5="Mindestprognose",IF(L5>=I5,1,0),IF(AND(ISNUMBER(I5),ISNUMBER(J5),I5<>J5),IF(AND(L5>=I5,L5<=J5),1,0),""))) -> 1 | X5: =IF(OR(F5="qualitativ",F5="fehlend",NOT(ISNUMBER(L5))),"nicht auswertbar",IF(F5="Punkt","Punktprognose",IF(AND(ISNUMBER(I5),ISNUMBER(J5),I5<>J5),IF(L5<I5,"unterhalb",IF(L5>J5,"oberhalb","innerhalb")),"nicht auswertbar"))) -> innerhalb | Y5: =IF(AND(ISNUMBER(S5),OR(G5="Marge %",G5="Wachstumsrate %")),ABS(S5),"") -> 0.001 | Z5: =IFERROR(VLOOKUP(A5,Unternehmen!$A:$D,4,FALSE()),"") -> Konsumgueter
A6: ADS | B6: 2022 | C6: Umsatz | D6: 2021: https://report.adidas-group.com/2021/de/serviceseiten/downloads/files/annual-report-adidas-gb21.pdf | E6: 198 | F6: Bandbreite | G6: Wachstumsrate % | H6: % (wb. Wachstumsrate) | I6: 0.12 | J6: 0.14 | K6: =L4 -> 0.16 | L6: 0.01 | M6: -15 PP | N6: -11 PP | O6: 2022: https://report.adidas-group.com/2022/de/_assets/downloads/annual-report-adidas-gb22.pdf | P6: 3 | R6: =IF(NOT(ISNUMBER(I6)),"",IF(F6="Mindestprognose",I6,IF(ISNUMBER(J6),(I6+J6)/2,I6))) -> 0.13 | S6: =IF(OR(R6="",NOT(ISNUMBER(L6))),"",R6-L6) -> 0.12 | T6: =IF(OR(S6="",G6<>"absolut",NOT(ISNUMBER(L6)),L6=0),"",S6/ABS(L6)) | U6: =IF(T6="","",ABS(T6)) | V6: =IF(OR(F6="Punkt",NOT(ISNUMBER(L6))),"",IF(F6="Mindestprognose",IF(L6>=I6,1,0),IF(AND(ISNUMBER(I6),ISNUMBER(J6),I6<>J6),IF(AND(L6>=I6,L6<=J6),1,0),""))) -> 0 | X6: =IF(OR(F6="qualitativ",F6="fehlend",NOT(ISNUMBER(L6))),"nicht auswertbar",IF(F6="Punkt","Punktprognose",IF(AND(ISNUMBER(I6),ISNUMBER(J6),I6<>J6),IF(L6<I6,"unterhalb",IF(L6>J6,"oberhalb","innerhalb")),"nicht auswertbar"))) -> unterhalb | Y6: =IF(AND(ISNUMBER(S6),OR(G6="Marge %",G6="Wachstumsrate %")),ABS(S6),"") -> 0.12 | Z6: =IFERROR(VLOOKUP(A6,Unternehmen!$A:$D,4,FALSE()),"") -> Konsumgueter
A7: ADS | B7: 2022 | C7: Operative Ergebnisgroesse | D7: 2021:https://report.adidas-group.com/2021/de/serviceseiten/downloads/files/annual-report-adidas-gb21.pdf | E7: 198 | F7: Bandbreite | G7: Marge % | H7: % (op. Marge) | I7: 0.105 | J7: 0.11 | K7: =L5 -> 0.094 | L7: 0.03 | M7: -6,4 PP | N7: -16,9 PP | O7: 2022: https://report.adidas-group.com/2022/de/_assets/downloads/annual-report-adidas-gb22.pdf | P7: 3 | R7: =IF(NOT(ISNUMBER(I7)),"",IF(F7="Mindestprognose",I7,IF(ISNUMBER(J7),(I7+J7)/2,I7))) -> 0.1075 | S7: =IF(OR(R7="",NOT(ISNUMBER(L7))),"",R7-L7) -> 0.0775 | T7: =IF(OR(S7="",G7<>"absolut",NOT(ISNUMBER(L7)),L7=0),"",S7/ABS(L7)) | U7: =IF(T7="","",ABS(T7)) | V7: =IF(OR(F7="Punkt",NOT(ISNUMBER(L7))),"",IF(F7="Mindestprognose",IF(L7>=I7,1,0),IF(AND(ISNUMBER(I7),ISNUMBER(J7),I7<>J7),IF(AND(L7>=I7,L7<=J7),1,0),""))) -> 0 | X7: =IF(OR(F7="qualitativ",F7="fehlend",NOT(ISNUMBER(L7))),"nicht auswertbar",IF(F7="Punkt","Punktprognose",IF(AND(ISNUMBER(I7),ISNUMBER(J7),I7<>J7),IF(L7<I7,"unterhalb",IF(L7>J7,"oberhalb","innerhalb")),"nicht auswertbar"))) -> unterhalb | Y7: =IF(AND(ISNUMBER(S7),OR(G7="Marge %",G7="Wachstumsrate %")),ABS(S7),"") -> 0.0775 | Z7: =IFERROR(VLOOKUP(A7,Unternehmen!$A:$D,4,FALSE()),"") -> Konsumgueter
A8: ADS | B8: 2023 | C8: Umsatz | D8: 2022: https://report.adidas-group.com/2022/de/_assets/downloads/annual-report-adidas-gb22.pdf | E8: 169 | F8: Bandbreite | G8: Wachstumsrate % | H8: % (wb. Wachstumsrate) | I8: -0.09 | J8: -0.07 | K8: =L7 -> 0.03 | L8: 0 | M8: -3 PP | N8: Positiv außerhalb Prognose (oberhalb) | O8: 2023: https://report.adidas-group.com/2023/de/_assets/downloads/annual-report-adidas-gb23.pdf | P8: 4 | R8: =IF(NOT(ISNUMBER(I8)),"",IF(F8="Mindestprognose",I8,IF(ISNUMBER(J8),(I8+J8)/2,I8))) -> -0.08 | S8: =IF(OR(R8="",NOT(ISNUMBER(L8))),"",R8-L8) -> -0.08 | T8: =IF(OR(S8="",G8<>"absolut",NOT(ISNUMBER(L8)),L8=0),"",S8/ABS(L8)) | U8: =IF(T8="","",ABS(T8)) | V8: =IF(OR(F8="Punkt",NOT(ISNUMBER(L8))),"",IF(F8="Mindestprognose",IF(L8>=I8,1,0),IF(AND(ISNUMBER(I8),ISNUMBER(J8),I8<>J8),IF(AND(L8>=I8,L8<=J8),1,0),""))) -> 0 | X8: =IF(OR(F8="qualitativ",F8="fehlend",NOT(ISNUMBER(L8))),"nicht auswertbar",IF(F8="Punkt","Punktprognose",IF(AND(ISNUMBER(I8),ISNUMBER(J8),I8<>J8),IF(L8<I8,"unterhalb",IF(L8>J8,"oberhalb","innerhalb")),"nicht auswertbar"))) -> oberhalb | Y8: =IF(AND(ISNUMBER(S8),OR(G8="Marge %",G8="Wachstumsrate %")),ABS(S8),"") -> 0.08 | Z8: =IFERROR(VLOOKUP(A8,Unternehmen!$A:$D,4,FALSE()),"") -> Konsumgueter
A9: ADS | B9: 2023 | C9: Operative Ergebnisgroesse | D9: 2022: https://report.adidas-group.com/2022/de/_assets/downloads/annual-report-adidas-gb22.pdf | E9: 169 | F9: Punkt | G9: absolut | H9: Mio. EUR | I9: -700 | J9: -700 | L9: 268 | N9: Positiv außerhalb Prognose (oberhalb) | O9: 2023: https://report.adidas-group.com/2023/de/_assets/downloads/annual-report-adidas-gb23.pdf | P9: 4 | Q9: METHODIK: Prognose -700 Mio (Verlust) vs. Ist +268 Mio -> Vorzeichenwechsel, relativer Fehler (-361 %) statistisch nicht sinnvoll interpretierbar; als Ausreisser behandeln oder in Robustheitsrechnung ausschliessen | R9: =IF(NOT(ISNUMBER(I9)),"",IF(F9="Mindestprognose",I9,IF(ISNUMBER(J9),(I9+J9)/2,I9))) -> -700 | S9: =IF(OR(R9="",NOT(ISNUMBER(L9))),"",R9-L9) -> -968 | T9: =IF(OR(S9="",G9<>"absolut",NOT(ISNUMBER(L9)),L9=0),"",S9/ABS(L9)) -> -3.6119403 | U9: =IF(T9="","",ABS(T9)) -> 3.6119403 | V9: =IF(OR(F9="Punkt",NOT(ISNUMBER(L9))),"",IF(F9="Mindestprognose",IF(L9>=I9,1,0),IF(AND(ISNUMBER(I9),ISNUMBER(J9),I9<>J9),IF(AND(L9>=I9,L9<=J9),1,0),""))) | X9: =IF(OR(F9="qualitativ",F9="fehlend",NOT(ISNUMBER(L9))),"nicht auswertbar",IF(F9="Punkt","Punktprognose",IF(AND(ISNUMBER(I9),ISNUMBER(J9),I9<>J9),IF(L9<I9,"unterhalb",IF(L9>J9,"oberhalb","innerhalb")),"nicht auswertbar"))) -> Punktprognose | Y9: =IF(AND(ISNUMBER(S9),OR(G9="Marge %",G9="Wachstumsrate %")),ABS(S9),"") | Z9: =IFERROR(VLOOKUP(A9,Unternehmen!$A:$D,4,FALSE()),"") -> Konsumgueter
A10: ADS | B10: 2024 | C10: Umsatz | D10: 2023: https://report.adidas-group.com/2023/de/_assets/downloads/annual-report-adidas-gb23.pdf | E10: 179 | F10: Bandbreite | G10: Wachstumsrate % | H10: % (wb. Wachstumsrate) | I10: 0.04 | J10: 0.06 | K10: =L8 -> 0 | L10: 0.12 | M10: 12 PP | N10: Positiv außerhalb Prognose (oberhalb) | O10: 2024: https://report.adidas-group.com/2024/de/_assets/downloads/annual-report-adidas-gb24.pdf | P10: 4 | R10: =IF(NOT(ISNUMBER(I10)),"",IF(F10="Mindestprognose",I10,IF(ISNUMBER(J10),(I10+J10)/2,I10))) -> 0.05 | S10: =IF(OR(R10="",NOT(ISNUMBER(L10))),"",R10-L10) -> -0.07 | T10: =IF(OR(S10="",G10<>"absolut",NOT(ISNUMBER(L10)),L10=0),"",S10/ABS(L10)) | U10: =IF(T10="","",ABS(T10)) | V10: =IF(OR(F10="Punkt",NOT(ISNUMBER(L10))),"",IF(F10="Mindestprognose",IF(L10>=I10,1,0),IF(AND(ISNUMBER(I10),ISNUMBER(J10),I10<>J10),IF(AND(L10>=I10,L10<=J10),1,0),""))) -> 0 | X10: =IF(OR(F10="qualitativ",F10="fehlend",NOT(ISNUMBER(L10))),"nicht auswertbar",IF(F10="Punkt","Punktprognose",IF(AND(ISNUMBER(I10),ISNUMBER(J10),I10<>J10),IF(L10<I10,"unterhalb",IF(L10>J10,"oberhalb","innerhalb")),"nicht auswertbar"))) -> oberhalb | Y10: =IF(AND(ISNUMBER(S10),OR(G10="Marge %",G10="Wachstumsrate %")),ABS(S10),"") -> 0.07 | Z10: =IFERROR(VLOOKUP(A10,Unternehmen!$A:$D,4,FALSE()),"") -> Konsumgueter
A11: ADS | B11: 2024 | C11: Operative Ergebnisgroesse | D11: 2023: https://report.adidas-group.com/2023/de/_assets/downloads/annual-report-adidas-gb23.pdf | E11: 179 | F11: Punkt | G11: absolut | H11: Mio. EUR | I11: 500 | J11: 500 | K11: =L9 -> 268 | L11: 1337 | M11: =L11-K11 -> 1069 | N11: Positiv außerhalb Prognose (oberhalb) | O11: 2024: https://report.adidas-group.com/2024/de/_assets/downloads/annual-report-adidas-gb24.pdf | P11: 4 | R11: =IF(NOT(ISNUMBER(I11)),"",IF(F11="Mindestprognose",I11,IF(ISNUMBER(J11),(I11+J11)/2,I11))) -> 500 | S11: =IF(OR(R11="",NOT(ISNUMBER(L11))),"",R11-L11) -> -837 | T11: =IF(OR(S11="",G11<>"absolut",NOT(ISNUMBER(L11)),L11=0),"",S11/ABS(L11)) -> -0.62602842 | U11: =IF(T11="","",ABS(T11)) -> 0.62602842 | V11: =IF(OR(F11="Punkt",NOT(ISNUMBER(L11))),"",IF(F11="Mindestprognose",IF(L11>=I11,1,0),IF(AND(ISNUMBER(I11),ISNUMBER(J11),I11<>J11),IF(AND(L11>=I11,L11<=J11),1,0),""))) | X11: =IF(OR(F11="qualitativ",F11="fehlend",NOT(ISNUMBER(L11))),"nicht auswertbar",IF(F11="Punkt","Punktprognose",IF(AND(ISNUMBER(I11),ISNUMBER(J11),I11<>J11),IF(L11<I11,"unterhalb",IF(L11>J11,"oberhalb","innerhalb")),"nicht auswertbar"))) -> Punktprognose | Y11: =IF(AND(ISNUMBER(S11),OR(G11="Marge %",G11="Wachstumsrate %")),ABS(S11),"") | Z11: =IFERROR(VLOOKUP(A11,Unternehmen!$A:$D,4,FALSE()),"") -> Konsumgueter
A12: ALV | B12: 2020 | C12: Operative Ergebnisgroesse | D12: 2019: https://www.allianz.com/content/dam/onemarketing/azcom/Allianz_com/investor-relations/en/results-reports/annual-report/ar-2019/de-GB-Gruppe-Geschaeftsbericht-Allianz-2019.pdf | E12: 67 | F12: Punkt mit Korridor | G12: absolut | H12: Mrd. EUR | I12: 11.5 | J12: 12.5 | K12: 11.855 | L12: 10.751 | M12: =L12-K12 -> -1.104 | N12: -750 Mio. EUR | O12: 2020: https://www.allianz.com/content/dam/onemarketing/azcom/Allianz_com/investor-relations/en/results-reports/annual-report/ar-2020/de-Allianz-Gruppe-Geschaeftsbericht-2020.pdf | P12: 67 | R12: =IF(NOT(ISNUMBER(I12)),"",IF(F12="Mindestprognose",I12,IF(ISNUMBER(J12),(I12+J12)/2,I12))) -> 12 | S12: =IF(OR(R12="",NOT(ISNUMBER(L12))),"",R12-L12) -> 1.249 | T12: =IF(OR(S12="",G12<>"absolut",NOT(ISNUMBER(L12)),L12=0),"",S12/ABS(L12)) -> 0.11617524 | U12: =IF(T12="","",ABS(T12)) -> 0.11617524 | V12: =IF(OR(F12="Punkt",NOT(ISNUMBER(L12))),"",IF(F12="Mindestprognose",IF(L12>=I12,1,0),IF(AND(ISNUMBER(I12),ISNUMBER(J12),I12<>J12),IF(AND(L12>=I12,L12<=J12),1,0),""))) -> 0 | X12: =IF(OR(F12="qualitativ",F12="fehlend",NOT(ISNUMBER(L12))),"nicht auswertbar",IF(F12="Punkt","Punktprognose",IF(AND(ISNUMBER(I12),ISNUMBER(J12),I12<>J12),IF(L12<I12,"unterhalb",IF(L12>J12,"oberhalb","innerhalb")),"nicht auswertbar"))) -> unterhalb | Y12: =IF(AND(ISNUMBER(S12),OR(G12="Marge %",G12="Wachstumsrate %")),ABS(S12),"") | Z12: =IFERROR(VLOOKUP(A12,Unternehmen!$A:$D,4,FALSE()),"") -> Versicherungen
A13: ALV | B13: 2020 | C13: Umsatz | D13: 2019: https://www.allianz.com/content/dam/onemarketing/azcom/Allianz_com/investor-relations/en/results-reports/annual-report/ar-2019/de-GB-Gruppe-Geschaeftsbericht-Allianz-2019.pdf | E13: 68 | F13: qualitativ | G13: absolut | H13: Mio. EUR | K13: 142.369 | L13: 140.455 | M13: =L13-K13 -> -1.914 | N13: Um 1.914 gesunken, obwohl es hätte steigen sollen | O13: 2020: https://www.allianz.com/content/dam/onemarketing/azcom/Allianz_com/investor-relations/en/results-reports/annual-report/ar-2020/de-Allianz-Gruppe-Geschaeftsbericht-2020.pdf | P13: 67 | R13: =IF(NOT(ISNUMBER(I13)),"",IF(F13="Mindestprognose",I13,IF(ISNUMBER(J13),(I13+J13)/2,I13))) | S13: =IF(OR(R13="",NOT(ISNUMBER(L13))),"",R13-L13) | T13: =IF(OR(S13="",G13<>"absolut",NOT(ISNUMBER(L13)),L13=0),"",S13/ABS(L13)) | U13: =IF(T13="","",ABS(T13)) | V13: =IF(OR(F13="Punkt",NOT(ISNUMBER(L13))),"",IF(F13="Mindestprognose",IF(L13>=I13,1,0),IF(AND(ISNUMBER(I13),ISNUMBER(J13),I13<>J13),IF(AND(L13>=I13,L13<=J13),1,0),""))) | W13: Moderates Wachstum | X13: =IF(OR(F13="qualitativ",F13="fehlend",NOT(ISNUMBER(L13))),"nicht auswertbar",IF(F13="Punkt","Punktprognose",IF(AND(ISNUMBER(I13),ISNUMBER(J13),I13<>J13),IF(L13<I13,"unterhalb",IF(L13>J13,"oberhalb","innerhalb")),"nicht auswertbar"))) -> nicht auswertbar | Y13: =IF(AND(ISNUMBER(S13),OR(G13="Marge %",G13="Wachstumsrate %")),ABS(S13),"") | Z13: =IFERROR(VLOOKUP(A13,Unternehmen!$A:$D,4,FALSE()),"") -> Versicherungen
A14: ALV | B14: 2021 | C14: Operative Ergebnisgroesse | D14: 2020: https://www.allianz.com/content/dam/onemarketing/azcom/Allianz_com/investor-relations/en/results-reports/annual-report/ar-2020/de-Allianz-Gruppe-Geschaeftsbericht-2020.pdf | E14: 80 | F14: Punkt mit Korridor | G14: absolut | H14: Mrd. EUR | I14: 11 | J14: 13 | K14: =L12 -> 10.751 | L14: 13.4 | M14: =L14-K14 -> 2.649 | N14: Positiv außerhalb Prognose (oberhalb) | O14: 2021: https://www.allianz.com/content/dam/onemarketing/azcom/Allianz_com/investor-relations/en/results-reports/annual-report/ar-2021/de-Allianz-Gruppe-Geschaeftsbericht-2021.pdf | P14: 78 | R14: =IF(NOT(ISNUMBER(I14)),"",IF(F14="Mindestprognose",I14,IF(ISNUMBER(J14),(I14+J14)/2,I14))) -> 12 | S14: =IF(OR(R14="",NOT(ISNUMBER(L14))),"",R14-L14) -> -1.4 | T14: =IF(OR(S14="",G14<>"absolut",NOT(ISNUMBER(L14)),L14=0),"",S14/ABS(L14)) -> -0.10447761 | U14: =IF(T14="","",ABS(T14)) -> 0.10447761 | V14: =IF(OR(F14="Punkt",NOT(ISNUMBER(L14))),"",IF(F14="Mindestprognose",IF(L14>=I14,1,0),IF(AND(ISNUMBER(I14),ISNUMBER(J14),I14<>J14),IF(AND(L14>=I14,L14<=J14),1,0),""))) -> 0 | X14: =IF(OR(F14="qualitativ",F14="fehlend",NOT(ISNUMBER(L14))),"nicht auswertbar",IF(F14="Punkt","Punktprognose",IF(AND(ISNUMBER(I14),ISNUMBER(J14),I14<>J14),IF(L14<I14,"unterhalb",IF(L14>J14,"oberhalb","innerhalb")),"nicht auswertbar"))) -> oberhalb | Y14: =IF(AND(ISNUMBER(S14),OR(G14="Marge %",G14="Wachstumsrate %")),ABS(S14),"") | Z14: =IFERROR(VLOOKUP(A14,Unternehmen!$A:$D,4,FALSE()),"") -> Versicherungen
A15: ALV | B15: 2021 | C15: Umsatz | D15: 2020: https://www.allianz.com/content/dam/onemarketing/azcom/Allianz_com/investor-relations/en/results-reports/annual-report/ar-2020/de-Allianz-Gruppe-Geschaeftsbericht-2020.pdf | E15: 80 | F15: qualitativ | G15: absolut | H15: Mio. EUR | K15: =L13 -> 140.455 | L15: 148.511 | M15: =L15-K15 -> 8.056 | N15: im Rahmen | O15: 2021: https://www.allianz.com/content/dam/onemarketing/azcom/Allianz_com/investor-relations/en/results-reports/annual-report/ar-2021/de-Allianz-Gruppe-Geschaeftsbericht-2021.pdf | P15: 78 | R15: =IF(NOT(ISNUMBER(I15)),"",IF(F15="Mindestprognose",I15,IF(ISNUMBER(J15),(I15+J15)/2,I15))) | S15: =IF(OR(R15="",NOT(ISNUMBER(L15))),"",R15-L15) | T15: =IF(OR(S15="",G15<>"absolut",NOT(ISNUMBER(L15)),L15=0),"",S15/ABS(L15)) | U15: =IF(T15="","",ABS(T15)) | V15: =IF(OR(F15="Punkt",NOT(ISNUMBER(L15))),"",IF(F15="Mindestprognose",IF(L15>=I15,1,0),IF(AND(ISNUMBER(I15),ISNUMBER(J15),I15<>J15),IF(AND(L15>=I15,L15<=J15),1,0),""))) | W15: Moderates Wachstum | X15: =IF(OR(F15="qualitativ",F15="fehlend",NOT(ISNUMBER(L15))),"nicht auswertbar",IF(F15="Punkt","Punktprognose",IF(AND(ISNUMBER(I15),ISNUMBER(J15),I15<>J15),IF(L15<I15,"unterhalb",IF(L15>J15,"oberhalb","innerhalb")),"nicht auswertbar"))) -> nicht auswertbar | Y15: =IF(AND(ISNUMBER(S15),OR(G15="Marge %",G15="Wachstumsrate %")),ABS(S15),"") | Z15: =IFERROR(VLOOKUP(A15,Unternehmen!$A:$D,4,FALSE()),"") -> Versicherungen
A16: ALV | B16: 2022 | C16: Operative Ergebnisgroesse | D16: 2021: https://www.allianz.com/content/dam/onemarketing/azcom/Allianz_com/investor-relations/en/results-reports/annual-report/ar-2021/de-Allianz-Gruppe-Geschaeftsbericht-2021.pdf | E16: 90 | F16: Punkt mit Korridor | G16: absolut | H16: Mrd. EUR | I16: 12.4 | J16: 14.4 | K16: =L14 -> 13.4 | L16: 14.164 | M16: =L16-K16 -> 0.764 | N16: im Rahmen | O16: 2022: https://www.allianz.com/content/dam/onemarketing/azcom/Allianz_com/investor-relations/en/results-reports/annual-report/ar-2022/de-Allianz-Gruppe-Geschaeftsbericht-2022.pdf | P16: 81 | R16: =IF(NOT(ISNUMBER(I16)),"",IF(F16="Mindestprognose",I16,IF(ISNUMBER(J16),(I16+J16)/2,I16))) -> 13.4 | S16: =IF(OR(R16="",NOT(ISNUMBER(L16))),"",R16-L16) -> -0.764 | T16: =IF(OR(S16="",G16<>"absolut",NOT(ISNUMBER(L16)),L16=0),"",S16/ABS(L16)) -> -0.053939565 | U16: =IF(T16="","",ABS(T16)) -> 0.053939565 | V16: =IF(OR(F16="Punkt",NOT(ISNUMBER(L16))),"",IF(F16="Mindestprognose",IF(L16>=I16,1,0),IF(AND(ISNUMBER(I16),ISNUMBER(J16),I16<>J16),IF(AND(L16>=I16,L16<=J16),1,0),""))) -> 1 | X16: =IF(OR(F16="qualitativ",F16="fehlend",NOT(ISNUMBER(L16))),"nicht auswertbar",IF(F16="Punkt","Punktprognose",IF(AND(ISNUMBER(I16),ISNUMBER(J16),I16<>J16),IF(L16<I16,"unterhalb",IF(L16>J16,"oberhalb","innerhalb")),"nicht auswertbar"))) -> innerhalb | Y16: =IF(AND(ISNUMBER(S16),OR(G16="Marge %",G16="Wachstumsrate %")),ABS(S16),"") | Z16: =IFERROR(VLOOKUP(A16,Unternehmen!$A:$D,4,FALSE()),"") -> Versicherungen
A17: ALV | B17: 2022 | C17: Umsatz | D17: 2021: https://www.allianz.com/content/dam/onemarketing/azcom/Allianz_com/investor-relations/en/results-reports/annual-report/ar-2021/de-Allianz-Gruppe-Geschaeftsbericht-2021.pdf | E17: 91 | F17: qualitativ | G17: absolut | H17: Mio. EUR | K17: =L15 -> 148.511 | L17: 152.671 | M17: =L17-K17 -> 4.16 | N17: im Rahmen | O17: 2022: https://www.allianz.com/content/dam/onemarketing/azcom/Allianz_com/investor-relations/en/results-reports/annual-report/ar-2022/de-Allianz-Gruppe-Geschaeftsbericht-2022.pdf | P17: 81 | R17: =IF(NOT(ISNUMBER(I17)),"",IF(F17="Mindestprognose",I17,IF(ISNUMBER(J17),(I17+J17)/2,I17))) | S17: =IF(OR(R17="",NOT(ISNUMBER(L17))),"",R17-L17) | T17: =IF(OR(S17="",G17<>"absolut",NOT(ISNUMBER(L17)),L17=0),"",S17/ABS(L17)) | U17: =IF(T17="","",ABS(T17)) | V17: =IF(OR(F17="Punkt",NOT(ISNUMBER(L17))),"",IF(F17="Mindestprognose",IF(L17>=I17,1,0),IF(AND(ISNUMBER(I17),ISNUMBER(J17),I17<>J17),IF(AND(L17>=I17,L17<=J17),1,0),""))) | W17: Moderates Wachstum | X17: =IF(OR(F17="qualitativ",F17="fehlend",NOT(ISNUMBER(L17))),"nicht auswertbar",IF(F17="Punkt","Punktprognose",IF(AND(ISNUMBER(I17),ISNUMBER(J17),I17<>J17),IF(L17<I17,"unterhalb",IF(L17>J17,"oberhalb","innerhalb")),"nicht auswertbar"))) -> nicht auswertbar | Y17: =IF(AND(ISNUMBER(S17),OR(G17="Marge %",G17="Wachstumsrate %")),ABS(S17),"") | Z17: =IFERROR(VLOOKUP(A17,Unternehmen!$A:$D,4,FALSE()),"") -> Versicherungen
A18: ALV | B18: 2023 | C18: Operative Ergebnisgroesse | D18: 2022: https://www.allianz.com/content/dam/onemarketing/azcom/Allianz_com/investor-relations/en/results-reports/annual-report/ar-2022/de-Allianz-Gruppe-Geschaeftsbericht-2022.pdf | E18: 94 | F18: Punkt mit Korridor | G18: absolut | H18: Mrd. EUR | I18: 13.2 | J18: 15.2 | K18: =L16 -> 14.164 | L18: 14.7 | M18: =L18-K18 -> 0.536 | N18: im Rahmen | O18: 2023: https://www.allianz.com/content/dam/onemarketing/azcom/Allianz_com/investor-relations/en/results-reports/annual-report/ar-2023/de-Allianz-Gruppe-Geschaeftsbericht-2023.pdf | P18: 128 | R18: =IF(NOT(ISNUMBER(I18)),"",IF(F18="Mindestprognose",I18,IF(ISNUMBER(J18),(I18+J18)/2,I18))) -> 14.2 | S18: =IF(OR(R18="",NOT(ISNUMBER(L18))),"",R18-L18) -> -0.5 | T18: =IF(OR(S18="",G18<>"absolut",NOT(ISNUMBER(L18)),L18=0),"",S18/ABS(L18)) -> -0.034013605 | U18: =IF(T18="","",ABS(T18)) -> 0.034013605 | V18: =IF(OR(F18="Punkt",NOT(ISNUMBER(L18))),"",IF(F18="Mindestprognose",IF(L18>=I18,1,0),IF(AND(ISNUMBER(I18),ISNUMBER(J18),I18<>J18),IF(AND(L18>=I18,L18<=J18),1,0),""))) -> 1 | X18: =IF(OR(F18="qualitativ",F18="fehlend",NOT(ISNUMBER(L18))),"nicht auswertbar",IF(F18="Punkt","Punktprognose",IF(AND(ISNUMBER(I18),ISNUMBER(J18),I18<>J18),IF(L18<I18,"unterhalb",IF(L18>J18,"oberhalb","innerhalb")),"nicht auswertbar"))) -> innerhalb | Y18: =IF(AND(ISNUMBER(S18),OR(G18="Marge %",G18="Wachstumsrate %")),ABS(S18),"") | Z18: =IFERROR(VLOOKUP(A18,Unternehmen!$A:$D,4,FALSE()),"") -> Versicherungen
A19: ALV | B19: 2023 | C19: Umsatz | D19: 2022: https://www.allianz.com/content/dam/onemarketing/azcom/Allianz_com/investor-relations/en/results-reports/annual-report/ar-2022/de-Allianz-Gruppe-Geschaeftsbericht-2022.pdf | E19: 94 | F19: Punkt | G19: Wachstumsrate % | H19: % (wb. Wachstumsrate) | I19: 0.07 | J19: 0.07 | L19: 0.08 | N19: Positiv außerhalb Prognose (oberhalb) | O19: 2023: https://www.allianz.com/content/dam/onemarketing/azcom/Allianz_com/investor-relations/en/results-reports/annual-report/ar-2023/de-Allianz-Gruppe-Geschaeftsbericht-2023.pdf | P19: 128 | R19: =IF(NOT(ISNUMBER(I19)),"",IF(F19="Mindestprognose",I19,IF(ISNUMBER(J19),(I19+J19)/2,I19))) -> 0.07 | S19: =IF(OR(R19="",NOT(ISNUMBER(L19))),"",R19-L19) -> -0.01 | T19: =IF(OR(S19="",G19<>"absolut",NOT(ISNUMBER(L19)),L19=0),"",S19/ABS(L19)) | U19: =IF(T19="","",ABS(T19)) | V19: =IF(OR(F19="Punkt",NOT(ISNUMBER(L19))),"",IF(F19="Mindestprognose",IF(L19>=I19,1,0),IF(AND(ISNUMBER(I19),ISNUMBER(J19),I19<>J19),IF(AND(L19>=I19,L19<=J19),1,0),""))) | W19: + 7% | X19: =IF(OR(F19="qualitativ",F19="fehlend",NOT(ISNUMBER(L19))),"nicht auswertbar",IF(F19="Punkt","Punktprognose",IF(AND(ISNUMBER(I19),ISNUMBER(J19),I19<>J19),IF(L19<I19,"unterhalb",IF(L19>J19,"oberhalb","innerhalb")),"nicht auswertbar"))) -> Punktprognose | Y19: =IF(AND(ISNUMBER(S19),OR(G19="Marge %",G19="Wachstumsrate %")),ABS(S19),"") -> 0.01 | Z19: =IFERROR(VLOOKUP(A19,Unternehmen!$A:$D,4,FALSE()),"") -> Versicherungen
A20: ALV | B20: 2024 | C20: Operative Ergebnisgroesse | D20: 2023: https://www.allianz.com/content/dam/onemarketing/azcom/Allianz_com/investor-relations/en/results-reports/annual-report/ar-2023/de-Allianz-Gruppe-Geschaeftsbericht-2023.pdf | E20: 130 | F20: Punkt mit Korridor | G20: absolut | H20: Mrd. EUR | I20: 13.8 | J20: 15.8 | K20: =L18 -> 14.7 | L20: 16 | M20: =L20-K20 -> 1.3 | N20: Positiv außerhalb Prognose (oberhalb) | O20: 2024: https://www.allianz.com/content/dam/onemarketing/azcom/Allianz_com/investor-relations/en/results-reports/annual-report/ar-2024/de-allianz-gruppe-geschaeftsbericht-2024.pdf | P20: 222 | R20: =IF(NOT(ISNUMBER(I20)),"",IF(F20="Mindestprognose",I20,IF(ISNUMBER(J20),(I20+J20)/2,I20))) -> 14.8 | S20: =IF(OR(R20="",NOT(ISNUMBER(L20))),"",R20-L20) -> -1.2 | T20: =IF(OR(S20="",G20<>"absolut",NOT(ISNUMBER(L20)),L20=0),"",S20/ABS(L20)) -> -0.075 | U20: =IF(T20="","",ABS(T20)) -> 0.075 | V20: =IF(OR(F20="Punkt",NOT(ISNUMBER(L20))),"",IF(F20="Mindestprognose",IF(L20>=I20,1,0),IF(AND(ISNUMBER(I20),ISNUMBER(J20),I20<>J20),IF(AND(L20>=I20,L20<=J20),1,0),""))) -> 0 | X20: =IF(OR(F20="qualitativ",F20="fehlend",NOT(ISNUMBER(L20))),"nicht auswertbar",IF(F20="Punkt","Punktprognose",IF(AND(ISNUMBER(I20),ISNUMBER(J20),I20<>J20),IF(L20<I20,"unterhalb",IF(L20>J20,"oberhalb","innerhalb")),"nicht auswertbar"))) -> oberhalb | Y20: =IF(AND(ISNUMBER(S20),OR(G20="Marge %",G20="Wachstumsrate %")),ABS(S20),"") | Z20: =IFERROR(VLOOKUP(A20,Unternehmen!$A:$D,4,FALSE()),"") -> Versicherungen
A21: ALV | B21: 2024 | C21: Umsatz | D21: 2023: https://www.allianz.com/content/dam/onemarketing/azcom/Allianz_com/investor-relations/en/results-reports/annual-report/ar-2023/de-Allianz-Gruppe-Geschaeftsbericht-2023.pdf | E21: 130 | F21: Punkt | G21: Wachstumsrate % | H21: % (wb. Wachstumsrate) | I21: 0.03 | J21: 0.03 | K21: =L19 -> 0.08 | L21: 0.083 | M21: 5,30 PP | N21: im Rahmen | O21: 2024: https://www.allianz.com/content/dam/onemarketing/azcom/Allianz_com/investor-relations/en/results-reports/annual-report/ar-2024/de-allianz-gruppe-geschaeftsbericht-2024.pdf | P21: 222 | R21: =IF(NOT(ISNUMBER(I21)),"",IF(F21="Mindestprognose",I21,IF(ISNUMBER(J21),(I21+J21)/2,I21))) -> 0.03 | S21: =IF(OR(R21="",NOT(ISNUMBER(L21))),"",R21-L21) -> -0.053 | T21: =IF(OR(S21="",G21<>"absolut",NOT(ISNUMBER(L21)),L21=0),"",S21/ABS(L21)) | U21: =IF(T21="","",ABS(T21)) | V21: =IF(OR(F21="Punkt",NOT(ISNUMBER(L21))),"",IF(F21="Mindestprognose",IF(L21>=I21,1,0),IF(AND(ISNUMBER(I21),ISNUMBER(J21),I21<>J21),IF(AND(L21>=I21,L21<=J21),1,0),""))) | W21: + 3% | X21: =IF(OR(F21="qualitativ",F21="fehlend",NOT(ISNUMBER(L21))),"nicht auswertbar",IF(F21="Punkt","Punktprognose",IF(AND(ISNUMBER(I21),ISNUMBER(J21),I21<>J21),IF(L21<I21,"unterhalb",IF(L21>J21,"oberhalb","innerhalb")),"nicht auswertbar"))) -> Punktprognose | Y21: =IF(AND(ISNUMBER(S21),OR(G21="Marge %",G21="Wachstumsrate %")),ABS(S21),"") -> 0.053 | Z21: =IFERROR(VLOOKUP(A21,Unternehmen!$A:$D,4,FALSE()),"") -> Versicherungen
A22: BAS | B22: 2020 | C22: Umsatz | D22: 2019: https://www.basf.com/dam/jcr:19509d83-1670-32bb-b58a-2ca8c594eb86/basf/www/global/documents/de/investor-relations/calendar-and-publications/reports/2020/BASF_Bericht_2019.pdf | E22: 136 | F22: Punkt mit Korridor | G22: absolut | H22: Mrd. EUR | I22: 60 | J22: 63 | K22: 59.316 | L22: 59.149 | M22: =L22-K22 -> -0.167 | N22: -0,85 Mrd. EUR | O22: 2020: https://www.basf.com/dam/jcr:14cf35ed-802f-3b49-8bef-363aa9646373/basf/www/global/documents/de/investor-relations/calendar-and-publications/reports/2021/BASF_Bericht_2020.pdf | P22: 156 | R22: =IF(NOT(ISNUMBER(I22)),"",IF(F22="Mindestprognose",I22,IF(ISNUMBER(J22),(I22+J22)/2,I22))) -> 61.5 | S22: =IF(OR(R22="",NOT(ISNUMBER(L22))),"",R22-L22) -> 2.351 | T22: =IF(OR(S22="",G22<>"absolut",NOT(ISNUMBER(L22)),L22=0),"",S22/ABS(L22)) -> 0.039747079 | U22: =IF(T22="","",ABS(T22)) -> 0.039747079 | V22: =IF(OR(F22="Punkt",NOT(ISNUMBER(L22))),"",IF(F22="Mindestprognose",IF(L22>=I22,1,0),IF(AND(ISNUMBER(I22),ISNUMBER(J22),I22<>J22),IF(AND(L22>=I22,L22<=J22),1,0),""))) -> 0 | X22: =IF(OR(F22="qualitativ",F22="fehlend",NOT(ISNUMBER(L22))),"nicht auswertbar",IF(F22="Punkt","Punktprognose",IF(AND(ISNUMBER(I22),ISNUMBER(J22),I22<>J22),IF(L22<I22,"unterhalb",IF(L22>J22,"oberhalb","innerhalb")),"nicht auswertbar"))) -> unterhalb | Y22: =IF(AND(ISNUMBER(S22),OR(G22="Marge %",G22="Wachstumsrate %")),ABS(S22),"") | Z22: =IFERROR(VLOOKUP(A22,Unternehmen!$A:$D,4,FALSE()),"") -> Chemie
A23: BAS | B23: 2020 | C23: Operative Ergebnisgroesse | D23: 2019: https://www.basf.com/dam/jcr:19509d83-1670-32bb-b58a-2ca8c594eb86/basf/www/global/documents/de/investor-relations/calendar-and-publications/reports/2020/BASF_Bericht_2019.pdf | E23: 136 | F23: Punkt mit Korridor | G23: absolut | H23: Mrd. EUR | I23: 4.2 | J23: 4.8 | K23: 4.536 | L23: 3.56 | M23: =L23-K23 -> -0.976 | N23: -0,64 Mrd. EUR | O23: 2020: https://www.basf.com/dam/jcr:14cf35ed-802f-3b49-8bef-363aa9646373/basf/www/global/documents/de/investor-relations/calendar-and-publications/reports/2021/BASF_Bericht_2020.pdf | P23: 156 | R23: =IF(NOT(ISNUMBER(I23)),"",IF(F23="Mindestprognose",I23,IF(ISNUMBER(J23),(I23+J23)/2,I23))) -> 4.5 | S23: =IF(OR(R23="",NOT(ISNUMBER(L23))),"",R23-L23) -> 0.94 | T23: =IF(OR(S23="",G23<>"absolut",NOT(ISNUMBER(L23)),L23=0),"",S23/ABS(L23)) -> 0.26404494 | U23: =IF(T23="","",ABS(T23)) -> 0.26404494 | V23: =IF(OR(F23="Punkt",NOT(ISNUMBER(L23))),"",IF(F23="Mindestprognose",IF(L23>=I23,1,0),IF(AND(ISNUMBER(I23),ISNUMBER(J23),I23<>J23),IF(AND(L23>=I23,L23<=J23),1,0),""))) -> 0 | X23: =IF(OR(F23="qualitativ",F23="fehlend",NOT(ISNUMBER(L23))),"nicht auswertbar",IF(F23="Punkt","Punktprognose",IF(AND(ISNUMBER(I23),ISNUMBER(J23),I23<>J23),IF(L23<I23,"unterhalb",IF(L23>J23,"oberhalb","innerhalb")),"nicht auswertbar"))) -> unterhalb | Y23: =IF(AND(ISNUMBER(S23),OR(G23="Marge %",G23="Wachstumsrate %")),ABS(S23),"") | Z23: =IFERROR(VLOOKUP(A23,Unternehmen!$A:$D,4,FALSE()),"") -> Chemie
A24: BAS | B24: 2021 | C24: Umsatz | D24: 2020: https://www.basf.com/dam/jcr:14cf35ed-802f-3b49-8bef-363aa9646373/basf/www/global/documents/de/investor-relations/calendar-and-publications/reports/2021/BASF_Bericht_2020.pdf | E24: 155 | F24: Punkt mit Korridor | G24: absolut | H24: Mrd. EUR | I24: 61 | J24: 64 | K24: =L22 -> 59.149 | L24: 78.598 | M24: =L24-K24 -> 19.449 | N24: Positiv außerhalb Prognose (oberhalb) | O24: 2021: https://www.basf.com/dam/jcr:e0618338-8da4-31ba-b2b3-165dd93a6fcf/basf/www/global/documents/de/investor-relations/calendar-and-publications/reports/2022/BASF_Bericht_2021.pdf | P24: 149 | R24: =IF(NOT(ISNUMBER(I24)),"",IF(F24="Mindestprognose",I24,IF(ISNUMBER(J24),(I24+J24)/2,I24))) -> 62.5 | S24: =IF(OR(R24="",NOT(ISNUMBER(L24))),"",R24-L24) -> -16.098 | T24: =IF(OR(S24="",G24<>"absolut",NOT(ISNUMBER(L24)),L24=0),"",S24/ABS(L24)) -> -0.20481437 | U24: =IF(T24="","",ABS(T24)) -> 0.20481437 | V24: =IF(OR(F24="Punkt",NOT(ISNUMBER(L24))),"",IF(F24="Mindestprognose",IF(L24>=I24,1,0),IF(AND(ISNUMBER(I24),ISNUMBER(J24),I24<>J24),IF(AND(L24>=I24,L24<=J24),1,0),""))) -> 0 | X24: =IF(OR(F24="qualitativ",F24="fehlend",NOT(ISNUMBER(L24))),"nicht auswertbar",IF(F24="Punkt","Punktprognose",IF(AND(ISNUMBER(I24),ISNUMBER(J24),I24<>J24),IF(L24<I24,"unterhalb",IF(L24>J24,"oberhalb","innerhalb")),"nicht auswertbar"))) -> oberhalb | Y24: =IF(AND(ISNUMBER(S24),OR(G24="Marge %",G24="Wachstumsrate %")),ABS(S24),"") | Z24: =IFERROR(VLOOKUP(A24,Unternehmen!$A:$D,4,FALSE()),"") -> Chemie
A25: BAS | B25: 2021 | C25: Operative Ergebnisgroesse | D25: 2020: https://www.basf.com/dam/jcr:14cf35ed-802f-3b49-8bef-363aa9646373/basf/www/global/documents/de/investor-relations/calendar-and-publications/reports/2021/BASF_Bericht_2020.pdf | E25: 155 | F25: Punkt mit Korridor | G25: absolut | H25: Mrd. EUR | I25: 4.1 | J25: 5 | K25: =L23 -> 3.56 | L25: 7.768 | M25: =L25-K25 -> 4.208 | N25: Positiv außerhalb Prognose (oberhalb) | O25: 2021: https://www.basf.com/dam/jcr:e0618338-8da4-31ba-b2b3-165dd93a6fcf/basf/www/global/documents/de/investor-relations/calendar-and-publications/reports/2022/BASF_Bericht_2021.pdf | P25: 149 | R25: =IF(NOT(ISNUMBER(I25)),"",IF(F25="Mindestprognose",I25,IF(ISNUMBER(J25),(I25+J25)/2,I25))) -> 4.55 | S25: =IF(OR(R25="",NOT(ISNUMBER(L25))),"",R25-L25) -> -3.218 | T25: =IF(OR(S25="",G25<>"absolut",NOT(ISNUMBER(L25)),L25=0),"",S25/ABS(L25)) -> -0.41426365 | U25: =IF(T25="","",ABS(T25)) -> 0.41426365 | V25: =IF(OR(F25="Punkt",NOT(ISNUMBER(L25))),"",IF(F25="Mindestprognose",IF(L25>=I25,1,0),IF(AND(ISNUMBER(I25),ISNUMBER(J25),I25<>J25),IF(AND(L25>=I25,L25<=J25),1,0),""))) -> 0 | X25: =IF(OR(F25="qualitativ",F25="fehlend",NOT(ISNUMBER(L25))),"nicht auswertbar",IF(F25="Punkt","Punktprognose",IF(AND(ISNUMBER(I25),ISNUMBER(J25),I25<>J25),IF(L25<I25,"unterhalb",IF(L25>J25,"oberhalb","innerhalb")),"nicht auswertbar"))) -> oberhalb | Y25: =IF(AND(ISNUMBER(S25),OR(G25="Marge %",G25="Wachstumsrate %")),ABS(S25),"") | Z25: =IFERROR(VLOOKUP(A25,Unternehmen!$A:$D,4,FALSE()),"") -> Chemie
A26: BAS | B26: 2022 | C26: Umsatz | D26: 2021: https://www.basf.com/dam/jcr:e0618338-8da4-31ba-b2b3-165dd93a6fcf/basf/www/global/documents/de/investor-relations/calendar-and-publications/reports/2022/BASF_Bericht_2021.pdf | E26: 149 | F26: Punkt mit Korridor | G26: absolut | H26: Mrd. EUR | I26: 74 | J26: 77 | K26: =L24 -> 78.598 | L26: 87.327 | M26: =L26-K26 -> 8.729 | N26: Positiv außerhalb Prognose (oberhalb) | O26: 2022: https://www.basf.com/dam/jcr:29580e49-03df-3dff-a5fe-e16171be6e3f/basf/www/global/documents/de/investor-relations/calendar-and-publications/reports/2023/BASF_Bericht_2022.pdf | P26: 155 | R26: =IF(NOT(ISNUMBER(I26)),"",IF(F26="Mindestprognose",I26,IF(ISNUMBER(J26),(I26+J26)/2,I26))) -> 75.5 | S26: =IF(OR(R26="",NOT(ISNUMBER(L26))),"",R26-L26) -> -11.827 | T26: =IF(OR(S26="",G26<>"absolut",NOT(ISNUMBER(L26)),L26=0),"",S26/ABS(L26)) -> -0.13543349 | U26: =IF(T26="","",ABS(T26)) -> 0.13543349 | V26: =IF(OR(F26="Punkt",NOT(ISNUMBER(L26))),"",IF(F26="Mindestprognose",IF(L26>=I26,1,0),IF(AND(ISNUMBER(I26),ISNUMBER(J26),I26<>J26),IF(AND(L26>=I26,L26<=J26),1,0),""))) -> 0 | X26: =IF(OR(F26="qualitativ",F26="fehlend",NOT(ISNUMBER(L26))),"nicht auswertbar",IF(F26="Punkt","Punktprognose",IF(AND(ISNUMBER(I26),ISNUMBER(J26),I26<>J26),IF(L26<I26,"unterhalb",IF(L26>J26,"oberhalb","innerhalb")),"nicht auswertbar"))) -> oberhalb | Y26: =IF(AND(ISNUMBER(S26),OR(G26="Marge %",G26="Wachstumsrate %")),ABS(S26),"") | Z26: =IFERROR(VLOOKUP(A26,Unternehmen!$A:$D,4,FALSE()),"") -> Chemie
A27: BAS | B27: 2022 | C27: Operative Ergebnisgroesse | D27: 2021: https://www.basf.com/dam/jcr:e0618338-8da4-31ba-b2b3-165dd93a6fcf/basf/www/global/documents/de/investor-relations/calendar-and-publications/reports/2022/BASF_Bericht_2021.pdf | E27: 149 | F27: Punkt mit Korridor | G27: absolut | H27: Mrd. EUR | I27: 6.6 | J27: 7.2 | K27: =L25 -> 7.768 | L27: 6.878 | M27: =L27-K27 -> -0.89 | N27: im Rahmen | O27: 2022: https://www.basf.com/dam/jcr:29580e49-03df-3dff-a5fe-e16171be6e3f/basf/www/global/documents/de/investor-relations/calendar-and-publications/reports/2023/BASF_Bericht_2022.pdf | P27: 155 | R27: =IF(NOT(ISNUMBER(I27)),"",IF(F27="Mindestprognose",I27,IF(ISNUMBER(J27),(I27+J27)/2,I27))) -> 6.9 | S27: =IF(OR(R27="",NOT(ISNUMBER(L27))),"",R27-L27) -> 0.022 | T27: =IF(OR(S27="",G27<>"absolut",NOT(ISNUMBER(L27)),L27=0),"",S27/ABS(L27)) -> 0.0031986042 | U27: =IF(T27="","",ABS(T27)) -> 0.0031986042 | V27: =IF(OR(F27="Punkt",NOT(ISNUMBER(L27))),"",IF(F27="Mindestprognose",IF(L27>=I27,1,0),IF(AND(ISNUMBER(I27),ISNUMBER(J27),I27<>J27),IF(AND(L27>=I27,L27<=J27),1,0),""))) -> 1 | X27: =IF(OR(F27="qualitativ",F27="fehlend",NOT(ISNUMBER(L27))),"nicht auswertbar",IF(F27="Punkt","Punktprognose",IF(AND(ISNUMBER(I27),ISNUMBER(J27),I27<>J27),IF(L27<I27,"unterhalb",IF(L27>J27,"oberhalb","innerhalb")),"nicht auswertbar"))) -> innerhalb | Y27: =IF(AND(ISNUMBER(S27),OR(G27="Marge %",G27="Wachstumsrate %")),ABS(S27),"") | Z27: =IFERROR(VLOOKUP(A27,Unternehmen!$A:$D,4,FALSE()),"") -> Chemie
A28: BAS | B28: 2023 | C28: Umsatz | D28: 2022: https://www.basf.com/dam/jcr:29580e49-03df-3dff-a5fe-e16171be6e3f/basf/www/global/documents/de/investor-relations/calendar-and-publications/reports/2023/BASF_Bericht_2022.pdf | E28: 155 | F28: Punkt mit Korridor | G28: absolut | H28: Mrd. EUR | I28: 84 | J28: 87 | K28: =L26 -> 87.327 | L28: 68.902 | M28: =L28-K28 -> -18.425 | N28: -15,10 Mrd. EUR | O28: 2023: https://www.basf.com/dam/jcr:dad0be3d-5bac-3832-a127-7c8cefeb7f41/basf/www/global/documents/de/investor-relations/calendar-and-publications/reports/2024/BASF_Bericht_2023.pdf | P28: 250 | R28: =IF(NOT(ISNUMBER(I28)),"",IF(F28="Mindestprognose",I28,IF(ISNUMBER(J28),(I28+J28)/2,I28))) -> 85.5 | S28: =IF(OR(R28="",NOT(ISNUMBER(L28))),"",R28-L28) -> 16.598 | T28: =IF(OR(S28="",G28<>"absolut",NOT(ISNUMBER(L28)),L28=0),"",S28/ABS(L28)) -> 0.24089286 | U28: =IF(T28="","",ABS(T28)) -> 0.24089286 | V28: =IF(OR(F28="Punkt",NOT(ISNUMBER(L28))),"",IF(F28="Mindestprognose",IF(L28>=I28,1,0),IF(AND(ISNUMBER(I28),ISNUMBER(J28),I28<>J28),IF(AND(L28>=I28,L28<=J28),1,0),""))) -> 0 | X28: =IF(OR(F28="qualitativ",F28="fehlend",NOT(ISNUMBER(L28))),"nicht auswertbar",IF(F28="Punkt","Punktprognose",IF(AND(ISNUMBER(I28),ISNUMBER(J28),I28<>J28),IF(L28<I28,"unterhalb",IF(L28>J28,"oberhalb","innerhalb")),"nicht auswertbar"))) -> unterhalb | Y28: =IF(AND(ISNUMBER(S28),OR(G28="Marge %",G28="Wachstumsrate %")),ABS(S28),"") | Z28: =IFERROR(VLOOKUP(A28,Unternehmen!$A:$D,4,FALSE()),"") -> Chemie
A29: BAS | B29: 2023 | C29: Operative Ergebnisgroesse | D29: 2022: https://www.basf.com/dam/jcr:29580e49-03df-3dff-a5fe-e16171be6e3f/basf/www/global/documents/de/investor-relations/calendar-and-publications/reports/2023/BASF_Bericht_2022.pdf | E29: 155 | F29: Punkt mit Korridor | G29: absolut | H29: Mrd. EUR | I29: 4.8 | J29: 5.4 | K29: =L27 -> 6.878 | L29: 3.806 | M29: =L29-K29 -> -3.072 | N29: -0,99 Mrd. EUR | O29: 2023: https://www.basf.com/dam/jcr:dad0be3d-5bac-3832-a127-7c8cefeb7f41/basf/www/global/documents/de/investor-relations/calendar-and-publications/reports/2024/BASF_Bericht_2023.pdf | P29: 244 | R29: =IF(NOT(ISNUMBER(I29)),"",IF(F29="Mindestprognose",I29,IF(ISNUMBER(J29),(I29+J29)/2,I29))) -> 5.1 | S29: =IF(OR(R29="",NOT(ISNUMBER(L29))),"",R29-L29) -> 1.294 | T29: =IF(OR(S29="",G29<>"absolut",NOT(ISNUMBER(L29)),L29=0),"",S29/ABS(L29)) -> 0.33998949 | U29: =IF(T29="","",ABS(T29)) -> 0.33998949 | V29: =IF(OR(F29="Punkt",NOT(ISNUMBER(L29))),"",IF(F29="Mindestprognose",IF(L29>=I29,1,0),IF(AND(ISNUMBER(I29),ISNUMBER(J29),I29<>J29),IF(AND(L29>=I29,L29<=J29),1,0),""))) -> 0 | X29: =IF(OR(F29="qualitativ",F29="fehlend",NOT(ISNUMBER(L29))),"nicht auswertbar",IF(F29="Punkt","Punktprognose",IF(AND(ISNUMBER(I29),ISNUMBER(J29),I29<>J29),IF(L29<I29,"unterhalb",IF(L29>J29,"oberhalb","innerhalb")),"nicht auswertbar"))) -> unterhalb | Y29: =IF(AND(ISNUMBER(S29),OR(G29="Marge %",G29="Wachstumsrate %")),ABS(S29),"") | Z29: =IFERROR(VLOOKUP(A29,Unternehmen!$A:$D,4,FALSE()),"") -> Chemie
A30: BAS | B30: 2024 | C30: Umsatz | D30: 2023: https://www.basf.com/dam/jcr:dad0be3d-5bac-3832-a127-7c8cefeb7f41/basf/www/global/documents/de/investor-relations/calendar-and-publications/reports/2024/BASF_Bericht_2023.pdf | F30: fehlend | Q30: Im Jahr 2024 fehl Umsatzprognose | R30: =IF(NOT(ISNUMBER(I30)),"",IF(F30="Mindestprognose",I30,IF(ISNUMBER(J30),(I30+J30)/2,I30))) | S30: =IF(OR(R30="",NOT(ISNUMBER(L30))),"",R30-L30) | T30: =IF(OR(S30="",G30<>"absolut",NOT(ISNUMBER(L30)),L30=0),"",S30/ABS(L30)) | U30: =IF(T30="","",ABS(T30)) | V30: =IF(OR(F30="Punkt",NOT(ISNUMBER(L30))),"",IF(F30="Mindestprognose",IF(L30>=I30,1,0),IF(AND(ISNUMBER(I30),ISNUMBER(J30),I30<>J30),IF(AND(L30>=I30,L30<=J30),1,0),""))) | X30: =IF(OR(F30="qualitativ",F30="fehlend",NOT(ISNUMBER(L30))),"nicht auswertbar",IF(F30="Punkt","Punktprognose",IF(AND(ISNUMBER(I30),ISNUMBER(J30),I30<>J30),IF(L30<I30,"unterhalb",IF(L30>J30,"oberhalb","innerhalb")),"nicht auswertbar"))) -> nicht auswertbar | Y30: =IF(AND(ISNUMBER(S30),OR(G30="Marge %",G30="Wachstumsrate %")),ABS(S30),"") | Z30: =IFERROR(VLOOKUP(A30,Unternehmen!$A:$D,4,FALSE()),"") -> Chemie
A31: BAS | B31: 2024 | C31: Operative Ergebnisgroesse | D31: 2023: https://www.basf.com/dam/jcr:dad0be3d-5bac-3832-a127-7c8cefeb7f41/basf/www/global/documents/de/investor-relations/calendar-and-publications/reports/2024/BASF_Bericht_2023.pdf | E31: 170 | F31: Punkt mit Korridor | G31: absolut | H31: Mrd. EUR | I31: 8 | J31: 8.6 | L31: 7.858 | N31: -0,14 Mrd. EUR | O31: 2024: https://www.basf.com/dam/jcr:d3e39e4b-cfca-49fc-8df8-984053c2a322/basf/www/global/documents/de/investor-relations/calendar-and-publications/reports/2025/BASF_Bericht_2024.pdf?vid=lIIH3WpJGD7dq3XzAnQeXe.7T7O_Rv6h | P31: 82 | Q31: KPI2 bei BASF: EBIT vor Sondereinfluessen (Kennzeichnung '*' aus KPI-Spalte hierher verschoben) | R31: =IF(NOT(ISNUMBER(I31)),"",IF(F31="Mindestprognose",I31,IF(ISNUMBER(J31),(I31+J31)/2,I31))) -> 8.3 | S31: =IF(OR(R31="",NOT(ISNUMBER(L31))),"",R31-L31) -> 0.442 | T31: =IF(OR(S31="",G31<>"absolut",NOT(ISNUMBER(L31)),L31=0),"",S31/ABS(L31)) -> 0.056248409 | U31: =IF(T31="","",ABS(T31)) -> 0.056248409 | V31: =IF(OR(F31="Punkt",NOT(ISNUMBER(L31))),"",IF(F31="Mindestprognose",IF(L31>=I31,1,0),IF(AND(ISNUMBER(I31),ISNUMBER(J31),I31<>J31),IF(AND(L31>=I31,L31<=J31),1,0),""))) -> 0 | X31: =IF(OR(F31="qualitativ",F31="fehlend",NOT(ISNUMBER(L31))),"nicht auswertbar",IF(F31="Punkt","Punktprognose",IF(AND(ISNUMBER(I31),ISNUMBER(J31),I31<>J31),IF(L31<I31,"unterhalb",IF(L31>J31,"oberhalb","innerhalb")),"nicht auswertbar"))) -> unterhalb | Y31: =IF(AND(ISNUMBER(S31),OR(G31="Marge %",G31="Wachstumsrate %")),ABS(S31),"") | Z31: =IFERROR(VLOOKUP(A31,Unternehmen!$A:$D,4,FALSE()),"") -> Chemie
A32: BAYN | B32: 2020 | C32: Umsatz | D32: 2019: https://www.bayer.com/sites/default/files/2020-11/geschaeftsbericht-2019-der-bayer-ag.pdf | E32: 87 | F32: Punkt mit Korridor | G32: absolut | H32: Mrd. EUR | I32: 44 | J32: 45 | K32: 43.545 | L32: 41.4 | M32: =L32-K32 -> -2.145 | N32: -2,60 Mrd. EUR | O32: 2020: https://www.bayer.com/sites/default/files/2021-02/Bayer-Geschaeftsbericht-2020.pdf | P32: 2 | R32: =IF(NOT(ISNUMBER(I32)),"",IF(F32="Mindestprognose",I32,IF(ISNUMBER(J32),(I32+J32)/2,I32))) -> 44.5 | S32: =IF(OR(R32="",NOT(ISNUMBER(L32))),"",R32-L32) -> 3.1 | T32: =IF(OR(S32="",G32<>"absolut",NOT(ISNUMBER(L32)),L32=0),"",S32/ABS(L32)) -> 0.074879227 | U32: =IF(T32="","",ABS(T32)) -> 0.074879227 | V32: =IF(OR(F32="Punkt",NOT(ISNUMBER(L32))),"",IF(F32="Mindestprognose",IF(L32>=I32,1,0),IF(AND(ISNUMBER(I32),ISNUMBER(J32),I32<>J32),IF(AND(L32>=I32,L32<=J32),1,0),""))) -> 0 | X32: =IF(OR(F32="qualitativ",F32="fehlend",NOT(ISNUMBER(L32))),"nicht auswertbar",IF(F32="Punkt","Punktprognose",IF(AND(ISNUMBER(I32),ISNUMBER(J32),I32<>J32),IF(L32<I32,"unterhalb",IF(L32>J32,"oberhalb","innerhalb")),"nicht auswertbar"))) -> unterhalb | Y32: =IF(AND(ISNUMBER(S32),OR(G32="Marge %",G32="Wachstumsrate %")),ABS(S32),"") | Z32: =IFERROR(VLOOKUP(A32,Unternehmen!$A:$D,4,FALSE()),"") -> Pharma & Healthcare
A33: BAYN | B33: 2020 | C33: Operative Ergebnisgroesse | D33: 2019: https://www.bayer.com/sites/default/files/2020-11/geschaeftsbericht-2019-der-bayer-ag.pdf | E33: 87 | F33: Punkt mit Korridor | G33: absolut | H33: Mrd. EUR | I33: 12.3 | J33: 12.6 | K33: 11.474 | L33: 11.461 | M33: =L33-K33 -> -0.013 | N33: -0,84 Mrd. EUR | O33: 2020: https://www.bayer.com/sites/default/files/2021-02/Bayer-Geschaeftsbericht-2020.pdf | P33: 2 | R33: =IF(NOT(ISNUMBER(I33)),"",IF(F33="Mindestprognose",I33,IF(ISNUMBER(J33),(I33+J33)/2,I33))) -> 12.45 | S33: =IF(OR(R33="",NOT(ISNUMBER(L33))),"",R33-L33) -> 0.989 | T33: =IF(OR(S33="",G33<>"absolut",NOT(ISNUMBER(L33)),L33=0),"",S33/ABS(L33)) -> 0.086292645 | U33: =IF(T33="","",ABS(T33)) -> 0.086292645 | V33: =IF(OR(F33="Punkt",NOT(ISNUMBER(L33))),"",IF(F33="Mindestprognose",IF(L33>=I33,1,0),IF(AND(ISNUMBER(I33),ISNUMBER(J33),I33<>J33),IF(AND(L33>=I33,L33<=J33),1,0),""))) -> 0 | X33: =IF(OR(F33="qualitativ",F33="fehlend",NOT(ISNUMBER(L33))),"nicht auswertbar",IF(F33="Punkt","Punktprognose",IF(AND(ISNUMBER(I33),ISNUMBER(J33),I33<>J33),IF(L33<I33,"unterhalb",IF(L33>J33,"oberhalb","innerhalb")),"nicht auswertbar"))) -> unterhalb | Y33: =IF(AND(ISNUMBER(S33),OR(G33="Marge %",G33="Wachstumsrate %")),ABS(S33),"") | Z33: =IFERROR(VLOOKUP(A33,Unternehmen!$A:$D,4,FALSE()),"") -> Pharma & Healthcare
A34: BAYN | B34: 2021 | C34: Umsatz | D34: 2020: https://www.bayer.com/sites/default/files/2021-02/Bayer-Geschaeftsbericht-2020.pdf | E34: 101 | F34: Punkt mit Korridor | G34: absolut | H34: Mrd. EUR | I34: 42 | J34: 43 | K34: =L32 -> 41.4 | L34: 44.081 | M34: =L34-K34 -> 2.681 | N34: Positiv außerhalb Prognose (oberhalb) | O34: 2021: https://www.bayer.com/sites/default/files/2022-03/Bayer-Geschaeftsbericht-2021.pdf | P34: 2 | R34: =IF(NOT(ISNUMBER(I34)),"",IF(F34="Mindestprognose",I34,IF(ISNUMBER(J34),(I34+J34)/2,I34))) -> 42.5 | S34: =IF(OR(R34="",NOT(ISNUMBER(L34))),"",R34-L34) -> -1.581 | T34: =IF(OR(S34="",G34<>"absolut",NOT(ISNUMBER(L34)),L34=0),"",S34/ABS(L34)) -> -0.035865793 | U34: =IF(T34="","",ABS(T34)) -> 0.035865793 | V34: =IF(OR(F34="Punkt",NOT(ISNUMBER(L34))),"",IF(F34="Mindestprognose",IF(L34>=I34,1,0),IF(AND(ISNUMBER(I34),ISNUMBER(J34),I34<>J34),IF(AND(L34>=I34,L34<=J34),1,0),""))) -> 0 | X34: =IF(OR(F34="qualitativ",F34="fehlend",NOT(ISNUMBER(L34))),"nicht auswertbar",IF(F34="Punkt","Punktprognose",IF(AND(ISNUMBER(I34),ISNUMBER(J34),I34<>J34),IF(L34<I34,"unterhalb",IF(L34>J34,"oberhalb","innerhalb")),"nicht auswertbar"))) -> oberhalb | Y34: =IF(AND(ISNUMBER(S34),OR(G34="Marge %",G34="Wachstumsrate %")),ABS(S34),"") | Z34: =IFERROR(VLOOKUP(A34,Unternehmen!$A:$D,4,FALSE()),"") -> Pharma & Healthcare
A35: BAYN | B35: 2021 | C35: Operative Ergebnisgroesse | D35: 2020: https://www.bayer.com/sites/default/files/2021-02/Bayer-Geschaeftsbericht-2020.pdf | E35: 101 | F35: Punkt | G35: Marge % | H35: % (op. Marge) | I35: 0.27 | J35: 0.27 | K35: 0.277 | L35: 0.254 | M35: -2,30 PP | N35: -2,40 PP | O35: 2021: https://www.bayer.com/sites/default/files/2022-03/Bayer-Geschaeftsbericht-2021.pdf | P35: 2 | R35: =IF(NOT(ISNUMBER(I35)),"",IF(F35="Mindestprognose",I35,IF(ISNUMBER(J35),(I35+J35)/2,I35))) -> 0.27 | S35: =IF(OR(R35="",NOT(ISNUMBER(L35))),"",R35-L35) -> 0.016 | T35: =IF(OR(S35="",G35<>"absolut",NOT(ISNUMBER(L35)),L35=0),"",S35/ABS(L35)) | U35: =IF(T35="","",ABS(T35)) | V35: =IF(OR(F35="Punkt",NOT(ISNUMBER(L35))),"",IF(F35="Mindestprognose",IF(L35>=I35,1,0),IF(AND(ISNUMBER(I35),ISNUMBER(J35),I35<>J35),IF(AND(L35>=I35,L35<=J35),1,0),""))) | X35: =IF(OR(F35="qualitativ",F35="fehlend",NOT(ISNUMBER(L35))),"nicht auswertbar",IF(F35="Punkt","Punktprognose",IF(AND(ISNUMBER(I35),ISNUMBER(J35),I35<>J35),IF(L35<I35,"unterhalb",IF(L35>J35,"oberhalb","innerhalb")),"nicht auswertbar"))) -> Punktprognose | Y35: =IF(AND(ISNUMBER(S35),OR(G35="Marge %",G35="Wachstumsrate %")),ABS(S35),"") -> 0.016 | Z35: =IFERROR(VLOOKUP(A35,Unternehmen!$A:$D,4,FALSE()),"") -> Pharma & Healthcare
A36: BAYN | B36: 2022 | C36: Umsatz | D36: 2021: https://www.bayer.com/sites/default/files/2022-03/Bayer-Geschaeftsbericht-2021.pdf | E36: 99 | F36: Punkt | G36: absolut | H36: Mrd. EUR | I36: 46 | J36: 46 | K36: =L34 -> 44.081 | L36: 50.739 | M36: =L36-K36 -> 6.658 | N36: Positiv außerhalb Prognose (oberhalb) | O36: 2022: https://www.bayer.com/sites/default/files/2023-02/Bayer-Geschaeftsbericht-2022.pdf | P36: 2 | R36: =IF(NOT(ISNUMBER(I36)),"",IF(F36="Mindestprognose",I36,IF(ISNUMBER(J36),(I36+J36)/2,I36))) -> 46 | S36: =IF(OR(R36="",NOT(ISNUMBER(L36))),"",R36-L36) -> -4.739 | T36: =IF(OR(S36="",G36<>"absolut",NOT(ISNUMBER(L36)),L36=0),"",S36/ABS(L36)) -> -0.093399555 | U36: =IF(T36="","",ABS(T36)) -> 0.093399555 | V36: =IF(OR(F36="Punkt",NOT(ISNUMBER(L36))),"",IF(F36="Mindestprognose",IF(L36>=I36,1,0),IF(AND(ISNUMBER(I36),ISNUMBER(J36),I36<>J36),IF(AND(L36>=I36,L36<=J36),1,0),""))) | X36: =IF(OR(F36="qualitativ",F36="fehlend",NOT(ISNUMBER(L36))),"nicht auswertbar",IF(F36="Punkt","Punktprognose",IF(AND(ISNUMBER(I36),ISNUMBER(J36),I36<>J36),IF(L36<I36,"unterhalb",IF(L36>J36,"oberhalb","innerhalb")),"nicht auswertbar"))) -> Punktprognose | Y36: =IF(AND(ISNUMBER(S36),OR(G36="Marge %",G36="Wachstumsrate %")),ABS(S36),"") | Z36: =IFERROR(VLOOKUP(A36,Unternehmen!$A:$D,4,FALSE()),"") -> Pharma & Healthcare
A37: BAYN | B37: 2022 | C37: Operative Ergebnisgroesse | D37: 2021: https://www.bayer.com/sites/default/files/2022-03/Bayer-Geschaeftsbericht-2021.pdf | E37: 99 | F37: Punkt | G37: Marge % | H37: % (op. Marge) | I37: 0.26 | J37: 0.26 | K37: =L35 -> 0.254 | L37: 0.266 | M37: 1,20 PP | N37: Positiv außerhalb Prognose (oberhalb) | O37: 2022: https://www.bayer.com/sites/default/files/2023-02/Bayer-Geschaeftsbericht-2022.pdf | P37: 2 | R37: =IF(NOT(ISNUMBER(I37)),"",IF(F37="Mindestprognose",I37,IF(ISNUMBER(J37),(I37+J37)/2,I37))) -> 0.26 | S37: =IF(OR(R37="",NOT(ISNUMBER(L37))),"",R37-L37) -> -0.006 | T37: =IF(OR(S37="",G37<>"absolut",NOT(ISNUMBER(L37)),L37=0),"",S37/ABS(L37)) | U37: =IF(T37="","",ABS(T37)) | V37: =IF(OR(F37="Punkt",NOT(ISNUMBER(L37))),"",IF(F37="Mindestprognose",IF(L37>=I37,1,0),IF(AND(ISNUMBER(I37),ISNUMBER(J37),I37<>J37),IF(AND(L37>=I37,L37<=J37),1,0),""))) | X37: =IF(OR(F37="qualitativ",F37="fehlend",NOT(ISNUMBER(L37))),"nicht auswertbar",IF(F37="Punkt","Punktprognose",IF(AND(ISNUMBER(I37),ISNUMBER(J37),I37<>J37),IF(L37<I37,"unterhalb",IF(L37>J37,"oberhalb","innerhalb")),"nicht auswertbar"))) -> Punktprognose | Y37: =IF(AND(ISNUMBER(S37),OR(G37="Marge %",G37="Wachstumsrate %")),ABS(S37),"") -> 0.006 | Z37: =IFERROR(VLOOKUP(A37,Unternehmen!$A:$D,4,FALSE()),"") -> Pharma & Healthcare
A38: BAYN | B38: 2023 | C38: Umsatz | D38: 2022: https://www.bayer.com/sites/default/files/2023-02/Bayer-Geschaeftsbericht-2022.pdf | E38: 112 | F38: Punkt mit Korridor | G38: absolut | H38: Mrd. EUR | I38: 50 | J38: 51 | K38: =L36 -> 50.739 | L38: 47.637 | M38: =L38-K38 -> -3.102 | N38: -2,36 Mrd. EUR | O38: 2023: https://www.bayer.com/sites/default/files/2024-03/bayer-geschaeftsbericht-2023.pdf | P38: 2 | R38: =IF(NOT(ISNUMBER(I38)),"",IF(F38="Mindestprognose",I38,IF(ISNUMBER(J38),(I38+J38)/2,I38))) -> 50.5 | S38: =IF(OR(R38="",NOT(ISNUMBER(L38))),"",R38-L38) -> 2.863 | T38: =IF(OR(S38="",G38<>"absolut",NOT(ISNUMBER(L38)),L38=0),"",S38/ABS(L38)) -> 0.060100342 | U38: =IF(T38="","",ABS(T38)) -> 0.060100342 | V38: =IF(OR(F38="Punkt",NOT(ISNUMBER(L38))),"",IF(F38="Mindestprognose",IF(L38>=I38,1,0),IF(AND(ISNUMBER(I38),ISNUMBER(J38),I38<>J38),IF(AND(L38>=I38,L38<=J38),1,0),""))) -> 0 | X38: =IF(OR(F38="qualitativ",F38="fehlend",NOT(ISNUMBER(L38))),"nicht auswertbar",IF(F38="Punkt","Punktprognose",IF(AND(ISNUMBER(I38),ISNUMBER(J38),I38<>J38),IF(L38<I38,"unterhalb",IF(L38>J38,"oberhalb","innerhalb")),"nicht auswertbar"))) -> unterhalb | Y38: =IF(AND(ISNUMBER(S38),OR(G38="Marge %",G38="Wachstumsrate %")),ABS(S38),"") | Z38: =IFERROR(VLOOKUP(A38,Unternehmen!$A:$D,4,FALSE()),"") -> Pharma & Healthcare
A39: BAYN | B39: 2023 | C39: Operative Ergebnisgroesse | D39: 2022: https://www.bayer.com/sites/default/files/2023-02/Bayer-Geschaeftsbericht-2022.pdf | E39: 112 | F39: Punkt mit Korridor | G39: absolut | H39: Mrd. EUR | I39: 12.5 | J39: 13 | K39: 13.5 | L39: 11.706 | M39: =L39-K39 -> -1.794 | N39: -0,79 Mrd. EUR | O39: 2023: https://www.bayer.com/sites/default/files/2024-03/bayer-geschaeftsbericht-2023.pdf | P39: 2 | R39: =IF(NOT(ISNUMBER(I39)),"",IF(F39="Mindestprognose",I39,IF(ISNUMBER(J39),(I39+J39)/2,I39))) -> 12.75 | S39: =IF(OR(R39="",NOT(ISNUMBER(L39))),"",R39-L39) -> 1.044 | T39: =IF(OR(S39="",G39<>"absolut",NOT(ISNUMBER(L39)),L39=0),"",S39/ABS(L39)) -> 0.089185033 | U39: =IF(T39="","",ABS(T39)) -> 0.089185033 | V39: =IF(OR(F39="Punkt",NOT(ISNUMBER(L39))),"",IF(F39="Mindestprognose",IF(L39>=I39,1,0),IF(AND(ISNUMBER(I39),ISNUMBER(J39),I39<>J39),IF(AND(L39>=I39,L39<=J39),1,0),""))) -> 0 | X39: =IF(OR(F39="qualitativ",F39="fehlend",NOT(ISNUMBER(L39))),"nicht auswertbar",IF(F39="Punkt","Punktprognose",IF(AND(ISNUMBER(I39),ISNUMBER(J39),I39<>J39),IF(L39<I39,"unterhalb",IF(L39>J39,"oberhalb","innerhalb")),"nicht auswertbar"))) -> unterhalb | Y39: =IF(AND(ISNUMBER(S39),OR(G39="Marge %",G39="Wachstumsrate %")),ABS(S39),"") | Z39: =IFERROR(VLOOKUP(A39,Unternehmen!$A:$D,4,FALSE()),"") -> Pharma & Healthcare
A40: BAYN | B40: 2024 | C40: Umsatz | D40: 2023: https://www.bayer.com/sites/default/files/2024-03/bayer-geschaeftsbericht-2023.pdf | E40: 101 | F40: Punkt mit Korridor | G40: absolut | H40: Mrd. EUR | I40: 46 | J40: 48 | K40: =L38 -> 47.637 | L40: 46.606 | M40: =L40-K40 -> -1.031 | N40: im Rahmen | O40: 2024: https://www.bayer.com/sites/default/files/2025-03/bayer-geschaeftsbericht-2024.pdf | P40: 2 | R40: =IF(NOT(ISNUMBER(I40)),"",IF(F40="Mindestprognose",I40,IF(ISNUMBER(J40),(I40+J40)/2,I40))) -> 47 | S40: =IF(OR(R40="",NOT(ISNUMBER(L40))),"",R40-L40) -> 0.394 | T40: =IF(OR(S40="",G40<>"absolut",NOT(ISNUMBER(L40)),L40=0),"",S40/ABS(L40)) -> 0.0084538471 | U40: =IF(T40="","",ABS(T40)) -> 0.0084538471 | V40: =IF(OR(F40="Punkt",NOT(ISNUMBER(L40))),"",IF(F40="Mindestprognose",IF(L40>=I40,1,0),IF(AND(ISNUMBER(I40),ISNUMBER(J40),I40<>J40),IF(AND(L40>=I40,L40<=J40),1,0),""))) -> 1 | X40: =IF(OR(F40="qualitativ",F40="fehlend",NOT(ISNUMBER(L40))),"nicht auswertbar",IF(F40="Punkt","Punktprognose",IF(AND(ISNUMBER(I40),ISNUMBER(J40),I40<>J40),IF(L40<I40,"unterhalb",IF(L40>J40,"oberhalb","innerhalb")),"nicht auswertbar"))) -> innerhalb | Y40: =IF(AND(ISNUMBER(S40),OR(G40="Marge %",G40="Wachstumsrate %")),ABS(S40),"") | Z40: =IFERROR(VLOOKUP(A40,Unternehmen!$A:$D,4,FALSE()),"") -> Pharma & Healthcare
...

Sheet Auswertung
